Workbook
Name NativeTimeline_Col_A: #N/A
Name NativeTimeline_日期: #N/A
Name 切片器_Col_B: #N/A
Name 切片器_Col_C: #N/A
Name 切片器_产品类别: #N/A
Name 切片器_区域: #N/A

Sheet Excel常用功能
A1: 数据工具 | B1: 数据选项卡——数据工具
A14: #VALUE! | B14: 分列 | C14: 对文本进行分列，变通用法，去除首位的空格。与TEXTSPLIT函数有共同的功能（TEXTSPLIT函数需Office2024及以上版本）
A16: #VALUE! | B16: 快速填充 | C16: 略，见填充
A18: #VALUE! | B18: 移除重复值 | C18: 注意对其他列的影响以及是否包含标题行选项
A20: #VALUE! | B20: 数据验证 | C20: 适合小量数据，内含数据验证窗口、圈释无效数据、清除验证标识圈三个选项。先建立数据验证规则，无效数据无法输入。
C21: 在已有数据上建立数据验证规则，可以使用圈释无效数据、清除验证标识圈功能，建议100行以内，10列以内的小量数据使用。
A23: #VALUE! | B23: 合并计算 | C23: 从单独的工作表汇总和报告结果，可以将每个工作表中的数据合并到主工作表中
A25: A | B25: B | D25: A | E25: B | G25: A | H25: B
A26: 2 | B26: 12 | D26: 1 | E26: 6 | G26: 1 | H26: 6
A27: 4 | B27: 14 | C27: = | D27: 2 | E27: 7 | F27: + | G27: 2 | H27: 7
A28: 6 | B28: 16 | D28: 3 | E28: 8 | G28: 3 | H28: 8
A29: 8 | B29: 18 | D29: 4 | E29: 9 | G29: 4 | H29: 9
A30: 10 | B30: 20 | D30: 5 | E30: 10 | G30: 5 | H30: 10
A32: #VALUE! | B32: 数据模型 | C32: 打开power pivot窗口，略，见power pivot
A34: #VALUE! | B34: 分析数据 | C34: 给出插入数据透视表、数据透视图、图表等预览建议。建议从这里进入相关功能。
A36: Col A | B36: Col B | C36: Col C | D36: Col D | E36: Col E | F36: Col F | G36: Col G | H36: Col H | I36: Col I
A37: Row 1 | B37: A | C37: 甲 | D37: 3 | E37: 51 | F37: 3 | G37: 100 | H37: 0.5 | I37: 一
A38: Row 2 | B38: B | C38: 乙 | D38: 5 | E38: 67 | F38: 5 | G38: 100 | H38: 0.7 | I38: 二
A39: Row 3 | B39: B | C39: 丙 | D39: 7 | E39: 43 | F39: 6 | G39: 100 | H39: 0.7 | I39: 三
A40: Row 4 | B40: C | C40: 甲 | D40: 3 | E40: 77 | F40: 7 | G40: 300 | H40: 0.4 | I40: 四
A41: Row 5 | B41: D | C41: 丙 | D41: 5 | E41: 43 | F41: 1 | G41: 300 | H41: 0.5 | I41: 五
A42: Row 6 | B42: A | C42: 乙 | D42: 9 | E42: 48 | F42: 10 | G42: 200 | H42: 0.2 | I42: 六
A43: Row 7 | B43: E | C43: 丙 | D43: 10 | E43: 19 | F43: 2 | G43: 200 | H43: 0.3 | I43: 七
A44: Row 8 | B44: F | C44: 甲 | D44: 8 | E44: 34 | F44: 4 | G44: 200 | H44: 0.9 | I44: 八
A45: Row 9 | B45: G | C45: 乙 | D45: 4 | E45: 55 | F45: 9 | G45: 500 | H45: 0.6 | I45: 九
A46: Row 10 | B46: D | C46: 丙 | D46: 6 | E46: 25 | F46: 8 | G46: 600 | H46: 0.3 | I46: 十
A49: 填充 | B49: 开始选项卡——编辑——填充
A68: 向下、向右、向上、向左 | C68: 略，适合填充公式
A70: 至同组工作表 | C70: 使用CTRL键选中多个工作表组成同组工作表
A72: 序列…
A89: 内容重排 | B89: 快速填充 | C89: 可用于拆分、组合文本等，略
A92: 排序和筛选 | B92: 数据选项卡——排序和筛选
A105: 升序、降序、排序 | C105: 略，注意对其他列的影响
A107: 筛选、清除、重新应用 | C107: 略
A109: 高级筛选 | C109: 通过设置条件区域来定义筛选规则，并可将结果原地筛选或复制到其他位置，用来取代快速筛选很合适，但是表功能更强大。
A111: Col A | B111: Col B | C111: Col C | E111: Col A | F111: Col C | I111: Col A | J111: Col B | K111: Col C
A112: 部门A | B112: 甲 | C112: 5000 | E112: 部门A | F112: >4000 | I112: 部门A | J112: 甲 | K112: 5000
A113: 部门A | B113: 乙 | C113: 3000 | E113: 部门B | I113: 部门B | J113: 丙 | K113: 6000
A114: 部门B | B114: 丙 | C114: 6000 | I114: 部门B | J114: 丁 | K114: 3000
A115: 部门B | B115: 丁 | C115: 3000 | I115: 部门A | J115: 甲 | K115: 8000
...

Sheet 图表类型
A1: 图表类型 | B1: 结构成分 | C1: 排序 | D1: 频率分布 | E1: 时间序列 | F1: 关联性
A2: 柱形图 | B2: 适用 | C2: 适用 | D2: 适用（连续） | E2: 适用（不连续）
A3: 折线图 | E3: 适用（连续） | F3: 适用（连续）
A4: 饼图 | B4: 适用
A5: 条形图 | C5: 适用
A6: 面积图 | E6: 适用
A7: XY散点图 | D7: 适用（不连续） | F7: 适用（不连续）
A8: 地图
A9: 股价图
A10: 曲面图
A11: 雷达图
A12: 树状图 | B12: 适用
A13: 旭日图（圆环图） | B13: 适用
A14: 直方图 | D14: 适用
A15: 箱型图
A16: 瀑布图
A17: 漏斗图 | B17: 适用
A18: 组合图

Sheet 表格+数据透视+切片器
A1: 日期 | B1: 区域 | C1: 产品类别 | D1: 销售员 | E1: 销售额 | F1: 订单数量 | H1: 求和项:销售额 | I1: 列标签
A2: 45658 | B2: 华东 | C2: 电子产品 | D2: 张三 | E2: 12000 | F2: 8 | H2: 行标签 | I2: 电子产品 | J2: 服装 | K2: 家居用品 | L2: 食品 | M2: 总计
A3: 45659 | B3: 华南 | C3: 家居用品 | D3: 李四 | E3: 9500 | F3: 6 | H3: 华北 | J3: 15500 | L3: 34500 | M3: 50000
A4: 45660 | B4: 华北 | C4: 食品 | D4: 王五 | E4: 7500 | F4: 5 | H4: 华东 | I4: 12000 | K4: 60500 | M4: 72500
A5: 45661 | B5: 西南 | C5: 服装 | D5: 赵六 | E5: 8500 | F5: 4 | H5: 华南 | I5: 74500 | K5: 9500 | M5: 84000
A6: 45662 | B6: 华东 | C6: 家居用品 | D6: 孙七 | E6: 9000 | F6: 7 | H6: 西南 | J6: 42000 | L6: 14000 | M6: 56000
A7: 45663 | B7: 华南 | C7: 电子产品 | D7: 周八 | E7: 10000 | F7: 9 | H7: 总计 | I7: 86500 | J7: 57500 | K7: 70000 | L7: 48500 | M7: 262500
A8: 45664 | B8: 华北 | C8: 服装 | D8: 吴九 | E8: 8000 | F8: 5
A9: 45665 | B9: 西南 | C9: 食品 | D9: 郑十 | E9: 7000 | F9: 4
A10: 45666 | B10: 华东 | C10: 家居用品 | D10: 张三 | E10: 8500 | F10: 6
A11: 45667 | B11: 华南 | C11: 电子产品 | D11: 李四 | E11: 10500 | F11: 8
A12: 45668 | B12: 华北 | C12: 食品 | D12: 王五 | E12: 6500 | F12: 4
A13: 45669 | B13: 西南 | C13: 服装 | D13: 赵六 | E13: 8500 | F13: 5
A14: 45670 | B14: 华东 | C14: 家居用品 | D14: 孙七 | E14: 8000 | F14: 6
A15: 45671 | B15: 华南 | C15: 电子产品 | D15: 周八 | E15: 10000 | F15: 7
A16: 45672 | B16: 华北 | C16: 服装 | D16: 吴九 | E16: 7500 | F16: 5
A17: 45673 | B17: 西南 | C17: 食品 | D17: 郑十 | E17: 7000 | F17: 4
A18: 45674 | B18: 华东 | C18: 家居用品 | D18: 张三 | E18: 9000 | F18: 7
A19: 45675 | B19: 华南 | C19: 电子产品 | D19: 李四 | E19: 11000 | F19: 8
... A31: 45687 | B31: 华南 | C31: 电子产品 | D31: 周八 | E31: 11000 | F31: 8

Sheet 函数清单
A1: 函数符号 | B1: =函数符号!A1 -> 相对引用与绝对引用
B2: =函数符号!A5 -> 双引号“”
B3: =函数符号!A9 -> 连接运算符&
B4: =函数符号!A12 -> 通配符 * ?
B5: @
A7: 文本函数 | B7: =文本!A2 -> TRIM | C7: =文本!B2 -> 除了单词之间的单个空格之外，移除文本中的所有空格
B8: =文本!A6 -> LEN | C8: =文本!B6 -> 返回文本字符串中的字符个数
B9: =文本!A9 -> LEFT | C9: =文本!B9 -> 从文本字符串的第一个字符开始返回指定个数的字符
B10: =文本!A17 -> RIGHT | C10: =文本!B17 -> 根据所指定的字符数返回文本字符串中最后一个或多个字符
B11: =文本!A25 -> MID | C11: =文本!B25 -> 返回文本字符串中从指定位置开始的特定数目的字符，该数目由用户指定
B12: =文本!A33 -> TEXT | C12: =文本!B33 -> 通过格式代码向数字应用格式，进而更改数字的显示方式
B13: =文本!A40 -> VALUE | C13: =文本!B40 -> 将表示数字的文本字符串转换为数字
B14: =文本!A44 -> VALUETOTEXT | C14: =文本!B44 -> 从任何指定值返回文本
B15: =文本!A51 -> CLEAN | C15: =文本!B51 -> 删除文本中所有不能打印的字符
B16: =文本!A56 -> SUBSTITUTE | C16: =文本!B56 -> 在文本字符串中用 new_text 替换 old_text
B17: =文本!A66 -> REPLACE | C17: =文本!B66 -> 根据指定的字符数，将部分文本字符串替换为不同的文本字符串
B18: =文本!A78 -> CONCAT | C18: =文本!B78 -> 合并来自多个区域和/或字符串的文本
B19: =文本!A81 -> FIND | C19: =文本!B81 -> 在第二个文本字符串中查找一个文本字符串，
A21: 统计函数 | B21: =统计!A2 -> SUM | C21: =统计!B2 -> 将单个值、单元格引用或是区域相加，或者将三者的组合相加
B22: =统计!A8 -> SUMIF | C22: =统计!B8 -> 对范围中符合指定条件的值求和
B23: =统计!A16 -> SUMIFS | C23: =统计!B16 -> 满足多个条件的全部参数的总量
B24: =统计!A23 -> SUMPRODUCT | C24: =统计!B23 -> 返回相应范围或数组的乘积的总和
B25: =统计!A31 -> COUNT | C25: =统计!B31 -> 计算包含数字的单元格个数以及参数列表中数字的个数
B26: =统计!A37 -> COUNTA | C26: =统计!B37 -> 计算范围中不为空的单元格的个数
B27: =统计!A43 -> COUNTBLANK | C27: =统计!B43 -> 计算范围中不为空的单元格的个数
B28: =统计!A48 -> COUNTIF | C28: =统计!B48 -> 统计满足某个条件的单元格的数量
B29: =统计!A55 -> COUNTIFS | C29: =统计!B55 -> 统计满足所有条件的次数
B30: =统计!A65 -> MAX | C30: =统计!B65 -> 返回一组值中的最大值
B31: =统计!A69 -> MIN | C31: =统计!B69 -> 参见MAX
B32: =统计!A71 -> AVERAGE | C32: =统计!B71 -> 返回参数的平均 (算术平均值)
B33: =统计!A75 -> AVERAGEIF | C33: =统计!B75 -> 返回某个区域内满足给定条件的所有单元格的平均值（算术平均值）
B34: =统计!A82 -> AVERAGEIFS | C34: =统计!B82 -> 返回满足多个条件的所有单元格的平均值（算术平均值）
B35: =统计!A89 -> MEDIAN | C35: =统计!B89 -> 返回一组已知数字的中值（中位数）
B36: =统计!A93 -> MODE | C36: =统计!B93 -> 返回数组或数据区域中最常出现或重复的值（众数）
B37: =统计!A97 -> MODE.SNGL | C37: =统计!B97 -> 返回在某一数组或数据区域中出现频率最多的数值
B38: =统计!A103 -> MODE.MULT | C38: =统计!B103 -> 返回一组数据或数据区域中出现频率最高或重复出现的数值的垂直数组
B39: =统计!A111 -> STDEV.S | C39: =统计!B111 -> 基于样本估算标准偏差（忽略样本中的逻辑值和文本）
B40: =统计!A117 -> STDEV.P | C40: =统计!B117 -> 计算基于以参数形式给出的整个样本总体的标准偏差（忽略逻辑值和文本）
B41: =统计!A123 -> VAR.S | C41: =统计!B123 -> 估算基于样本的方差（忽略样本中的逻辑值和文本）
B42: =统计!A129 -> VAR.P | C42: =统计!B129 -> 计算基于整个样本总体的方差（忽略样本总体中的逻辑值和文本）
...

Sheet 函数符号
A1: 相对引用与绝对引用
A2: 绝对引用的快捷键：F4 | B2: 1 | C2: 2 | D2: 3 | E2: 4
A3: 绝对引用符号：美元符号$ | B3: =B2 -> 1 | C3: =$C2 -> 2 | D3: =D$2 -> 3 | E3: =$E$2 -> 4
A5: 双引号“”
A6: 双引号通常用于表示空字符串或是用来包含文字数据
A7: “”：表示一个空值
A9: 连接运算符&
A10: 连接运算符用于将两个或多个字符串连接起来 | D10: =E10&F10 -> AB | E10: A | F10: B
A12: 通配符 * ?
A13: *（星号）：代表任何数量的字符，包括零个字符 | E13: =COUNTIF(F13:J13, "*手机*") -> 3 | F13: Apple手机 | G13: 小米手机 | H13: 小米手环 | I13: Apple Watch | J13: Android手机
A14: `?`（问号）：代表单一任意字符 | E14: =COUNTIF(F14:J14, "小米??") -> 2 | F14: Apple手机 | G14: 小米手机 | H14: 小米手环 | I14: Apple Watch | J14: Android手机
A16: 普通单元格公式（动态数组 Excel）：隐式交集操作符，取与当前单元格同行/列的单个值
A18: 10
A19: 20
A20: 30 | C20: =A18:A22 -> 30
A21: 40 | C21: =A18:A22 -> 40
A22: 50
A24: 表格（Table）中的结构化引用：表示“当前行”的数据，如 [@列名]
A26: Col A | B26: 列1 | C26: 列2
A27: 10 | C27: =表A[[#This Row],[Col A]]*0.1 -> 1
A28: 20 | C28: =表A[[#This Row],[Col A]]*0.1 -> 2
A29: 30 | C29: =表A[[#This Row],[Col A]]*0.1 -> 3
A30: 40 | C30: =表A[[#This Row],[Col A]]*0.1 -> 4
A31: 50 | C31: =表A[[#This Row],[Col A]]*0.1 -> 5
A33: 在旧版 Excel（如 Excel 2016 及更早）中，@ 不是合法的公式符号，不会出现这种用法。

Sheet 文本
A1: 函数 | B1: 说明摘要 | C1: 语法 | D1: 参数说明 | E1: 使用示例
A2: TRIM | B2: 除了单词之间的单个空格之外，移除文本中的所有空格 | C2: TRIM(text) | D2: text 必需。要从中移除空格的文本 | E2: 转化后 | F2: text
E3: =TRIM(F3) -> abcd efg | F3: abcd efg
E4: =TRIM(F4) -> 你好 世界 | F4: 你好 世界
A6: LEN | B6: 返回文本字符串中的字符个数 | C6: LEN(text) | D6: text 必需。要查找其长度的文本 | E6: 结果 | F6: text
E7: =LEN(F7) -> 8 | F7: ABCD FEG | G7: 空格将作为字符进行计数
A9: LEFT | B9: 从文本字符串的第一个字符开始返回指定个数的字符 | C9: LEFT(text, [num_chars]) | D9: 文本 必需。包含要提取的字符的文本字符串 | E9: 结果 | F9: text | G9: num_chars
E10: =LEFT(F10) -> a | F10: abcdefg
D11: num_chars 可选。指定要由 LEFT 提取的字符的数量 | E11: =LEFT(F11) -> 你 | F11: 你好世界
E12: =LEFT(F12,G12) -> abcd | F12: abcdefg | G12: 4
E13: =LEFT(F13,G13) -> 你好 | F13: 你好世界 | G13: 2
D14: 省略 num_chars，则假定其值为 1 | E14: =LEFT(F14,G14) -> abcdefg | F14: abcdefg | G14: 10
E15: =LEFT(F15,G15) -> 你好世界 | F15: 你好世界 | G15: 10
A17: RIGHT | B17: 根据所指定的字符数返回文本字符串中最后一个或多个字符 | C17: RIGHT(text,[num_chars]) | D17: 参照LEFT相同 | E17: 结果 | F17: text | G17: num_chars
E18: =RIGHT(F18) -> g | F18: abcdefg
E19: =RIGHT(F19) -> 界 | F19: 你好世界
E20: =RIGHT(F20,G20) -> defg | F20: abcdefg | G20: 4
E21: =RIGHT(F21,G21) -> 世界 | F21: 你好世界 | G21: 2
E22: =RIGHT(F22,G22) -> abcdefg | F22: abcdefg | G22: 10
E23: =RIGHT(F23,G23) -> 你好世界 | F23: 你好世界 | G23: 10
A25: MID | B25: 返回文本字符串中从指定位置开始的特定数目的字符，该数目由用户指定 | C25: MID(text, start_num, num_chars) | D25: text 必需。包含要提取字符的文本字符串 | E25: 结果 | F25: text | G25: start_num | H25: num_chars
E26: =MID(F26,G26,H26) -> cdef | F26: abcdefg | G26: 3 | H26: 4
D27: start_num 必需。文本中要提取的第一个字符的位置 | E27: =MID(F27,G27,H27) -> 好世 | F27: 你好世界 | G27: 2 | H27: 2
E28: =MID(F28,G28,H28) | F28: abcdefg | G28: 10 | H28: 4
E29: =MID(F29,G29,H29) | F29: 你好世界 | G29: 10 | H29: 2
D30: num_chars 必需。指定希望 MID 从文本中返回字符的个数 | E30: =MID(F30,G30,H30) -> cdefg | F30: abcdefg | G30: 3 | H30: 10
E31: =MID(F31,G31,H31) -> 好世界 | F31: 你好世界 | G31: 2 | H31: 10
A33: TEXT | B33: 通过格式代码向数字应用格式，进而更改数字的显示方式 | C33: TEXT(value, format_text) | D33: value 要转换为文本的数值 | E33: 转化后 | F33: value | G33: format_text
E34: =TEXT(F34,G34) -> $1,234.57 | F34: 1234.567 | G34: $#,##0.00
D35: format_text 一个文本字符串，定义要应用于所提供值的格式 | E35: =TEXT(F35,G35) -> 01/08/26 | F35: =TODAY() -> 46030 | G35: MM/DD/YY
E36: =TEXT(F36,G36) -> Thursday | F36: =TODAY() -> 46030 | G36: DDDD
E37: =TEXT(F37,G37) -> 2:46 PM | F37: =NOW() -> 46030.616 | G37: H:MM AM/PM
E38: =TEXT(F38,G38) -> 28.50% | F38: 0.285 | G38: 0.00%
A40: VALUE | B40: 将表示数字的文本字符串转换为数字 | C40: VALUE(text) | D40: text 必需。用引号括起来的文本或包含要转换文本的单元格的引用 | E40: 转化后 | F40: value
E41: =VALUE(F41) -> 1000 | F41: 1,000
E42: =VALUE(F42) -> 123345 | F42: 123,345.00
A44: VALUETOTEXT | B44: 从任何指定值返回文本 | C44: VALUETOTEXT(value, [format]) | D44: value 必需。以文本形式返回的值 | E44: 转化后 | F44: value | G44: [format]
E45: =_xlfn.VALUETOTEXT(F45) -> 12345.8967 | F45: 12345.897
D46: format 可选。返回的数据的格式，0 默认。简明格式。1 包含转义字符和行定界符的严格格式 | E46: =_xlfn.VALUETOTEXT(F46,G46) -> 12345.8967 | F46: 12345.897 | G46: 0
E47: =_xlfn.VALUETOTEXT(F47,G47) -> 12345.8967 | F47: 12345.897 | G47: 1
...

Sheet 统计
A1: 函数 | B1: 说明摘要 | C1: 语法 | D1: 参数说明 | E1: 使用示例
A2: SUM | B2: 将单个值、单元格引用或是区域相加，或者将三者的组合相加 | C2: SUM(number1,[number2],...) | D2: number1 必需 | E2: 结果 | F2: number1 | G2: number2 | H2: number3 | I2: number4
D3: number2-255 可选 | E3: =SUM(F3) -> 1 | F3: 1
E4: =SUM(F4:G4) -> 5 | F4: 2 | G4: 3
E5: =SUM(F5,G5:H5) -> 15 | F5: 4 | G5: 5 | H5: 6
E6: =SUM(F6:G6,H6:I6) -> 17 | F6: 7 | G6: & | H6: nine | I6: 10
A8: SUMIF | B8: 对范围中符合指定条件的值求和 | C8: SUMIF(range, criteria, [sum_range]) | D8: range 必需 | E8: 结果 | F8: range | G8: criteria | H8: sum_range
D9: criteria 必需 | E9: =SUMIF(F9:F12,G9,H9:H12) -> 5 | F9: A | G9: B | H9: 1
C10: criteria 以数字、表达式、单元格参考、文本或函数的形式来定义将添加哪些单元格。可包括的通配符字符 - 问号（？）以匹配任意单个字符，星号（*）以匹配任意字符序列。如果要查找实际的问号或星号，需在该字符前键入波形符（~） | D10: sum_range 可选。要添加的实际单元格。 如果省略sum_range参数，会添加范围参数中指定的单元格 | F10: B | H10: 2
E11: =SUMIF(H9:H13,G11) -> 4 | F11: B | G11: 2 | H11: 3
F12: C | H12: 2
F13: D | H13: 5
A16: SUMIFS | B16: 满足多个条件的全部参数的总量 | C16: SUMIFS(sum_range, criteria_range1, criteria1, [criteria_range2, criteria2], ...) | D16: Sum_range、Criteria_range1、Criteria1（必需） | E16: 结果 | F16: Sum_range | G16: Criteria1 | H16: Criteria_range1 | I16: Criteria_range2
E17: =SUMIFS(F17:F21,H17:H21,G17,I17:I21,G19) -> 5 | F17: 1 | G17: B | H17: A | I17: 甲
F18: 2 | G18: criteria2 | H18: B | I18: 乙
D19: Criteria_range2, criteria2, … 最多可以输入 127 个区域/条件对 | F19: 3 | G19: 乙 | H19: B | I19: 乙
F20: 2 | H20: B | I20: 丙
F21: 5 | H21: C | I21: 丁
A23: SUMPRODUCT | B23: 返回相应范围或数组的乘积的总和 | C23: SUMPRODUCT (array1， [array2]， [array3]， ...) | D23: array1 必需 | E23: 结果 | F23: array
D24: [array2]、[array3],... 可选。2 到 255 个数组参数，其相应元素需要进行相乘并求和 | E24: =SUMPRODUCT(F24,G24,H24,I24) -> 24 | F24: 1 | G24: 2 | H24: 3 | I24: 4
C25: 将分隔数组参数的逗号替换为所需的算术运算符 (*、/、+、-) 。 执行所有操作后，将像往常一样对结果进行求和 | E25: =SUMPRODUCT(F25:I25) -> 10 | F25: 1 | G25: 2 | H25: 3 | I25: 4
E26: =SUMPRODUCT(F26:I26) -> 26 | F26: 5 | G26: 6 | H26: 7 | I26: 8
E27: =SUMPRODUCT(F25:I25,F26:I26) -> 70 | F27: =F25*F26 -> 5 | G27: =G25*G26 -> 12 | H27: =H25*H26 -> 21 | I27: =I25*I26 -> 32
C28: 例如： | E28: =SUM(F27:I27) -> 70
C29: SUMPRODUCT ( (B2：B9=B12) * (C2：C9=C12) *D2：D9)
A31: COUNT | B31: 计算包含数字的单元格个数以及参数列表中数字的个数 | C31: COUNT(value1, [value2], ...) | D31: value1 必需。要计算其中数字的个数的第一项、单元格引用或区域 | E31: 结果 | F31: value1
E32: =COUNT(F32:I32) -> 1 | F32: A | H32: # | I32: 3
E33: =COUNT("A","#",3) -> 1
D34: value2, ... 可选。最多可包含 255 个
A37: COUNTA | B37: 计算范围中不为空的单元格的个数 | C37: COUNTA(value1, [value2], ...) | D37: value1 必需。要计算其中数字的个数的第一项、单元格引用或区域 | E37: 结果 | F37: value1
E38: =COUNTA(F38:I38) -> 3 | F38: A | H38: # | I38: 3
E39: =COUNTA("A","#",3) -> 3
D40: value2, ... 可选。最多可包含 255 个
A43: COUNTBLANK | B43: 计算范围中不为空的单元格的个数 | C43: COUNTA(value1, [value2], ...) | D43: value1 必需。表示要计数的值的第一个参数 | E43: 结果 | F43: value1
E44: =COUNTBLANK(F44:I44) -> 1 | F44: A | H44: # | I44: 3
D45: value2, ... 可选。最多可包含 255 个参数
A48: COUNTIF | B48: 统计满足某个条件的单元格的数量 | C48: COUNTIF(range, criteria) | D48: criteria_range 必需。在其中计算关联条件的区域 | E48: 结果 | F48: criteria_range
E49: =COUNTIF(F49:H49,I49) -> 2 | F49: 深圳 | G49: 上海 | H49: 深圳 | I49: 深圳
E50: =COUNTIF(F50:H50,"<>"&I50) -> 2 | F50: 深圳 | G50: 上海 | H50: 深圳 | I50: 上海
D51: criteria 必需。条件的形式为数字、表达式、单元格引用或文本 | E51: =COUNTIF(F51:I51,">="&100) -> 2 | F51: 45 | G51: 36 | H51: 234 | I51: 100
...

Sheet 查找引用
A1: 函数 | B1: 说明摘要 | C1: 语法 | D1: 参数说明 | E1: 使用示例
A2: XLOOKUP | B2: 按行查找表或区域中的项 | C2: XLOOKUP(lookup_value, lookup_array, return_array, [if_not_found], [match_mode], [search_mode]) | E2: 结果 | F2: lookup_value | G2: lookup_array | H2: return_array | I2: [if_not_found]
E3: =_xlfn.XLOOKUP(F3,G3:G7,H3:H7) -> 3 | F3: C | G3: A | H3: 1 | I3: 0
E4: =_xlfn.XLOOKUP(F4,G3:G7,H3:H7) -> #N/A | F4: F | G4: B | H4: 2 | I4: [match_mode]
A5: lookup_value | B5: 必填 | C5: 要搜索的值 | E5: =_xlfn.XLOOKUP(F5,G3:G7,H3:H7,I3) -> 0 | F5: F | G5: C | H5: 3 | I5: -1
E6: =_xlfn.XLOOKUP(F6,G3:G7,H3:H7,I3,I5) -> 5 | F6: F | G6: C | H6: 4 | I6: [search_mode]
A7: lookup_array | B7: 必需​ | C7: 要搜索的数组或区域 | E7: =_xlfn.XLOOKUP(F7,G3:G7,H3:H7,I3,I5,I7) -> 4 | F7: C | G7: E | H7: 5 | I7: -1
A9: return_array | B9: 必需 | C9: 要返回的数组或区域
A11: [if_not_found] | B11: 可选 | C11: 如果未找到有效的匹配项，则返回你提供的 [if_not_found] 文本。
C12: 如果未找到有效的匹配项，并且缺少 [if_not_found]，则返回 #N/A 。
A14: [match_mode] | B14: 可选。指定匹配类型 | C14: 0 - 完全匹配。 如果未找到，则返回 #N/A。 这是默认选项。
C15: -1 - 完全匹配。 如果没有找到,则返回下一个较小的项。
C16: 1 - 完全匹配。 如果没有找到，则返回下一个较大的项。
C17: 2 - 通配符匹配，其中 *, ? 和 ~ 有特殊含义。
A19: [search_mode] | B19: 可选。指定要使用的搜索模式 | C19: 1 - 从第一项开始执行搜索。 这是默认选项。
C20: -1 - 从最后一项开始执行反向搜索。
C21: 2 - 执行依赖于 lookup_array 按升序排序的二进制搜索。 如果未排序，将返回无效结果。
C22: -2 - 执行依赖于 lookup_array 按降序排序的二进制搜索。 如果未排序，将返回无效结果。
A24: INDIRECT | B24: 返回由文本字符串指定的引用 | C24: INDIRECT(ref_text, [a1]) | D24: Ref_text 必需 | E24: 结果 | F24: ref_text | G24: A1
D25: A1 可选。 指定包含在单元格 ref_text 中的引用的类型 | E25: {=INDIRECT(F25)} -> 111 | F25: H25 | H25: 111
C26: Ref_text 必需。对包含 A1 样式引用、R1C1 样式引用、定义为引用的名称或作为文本字符串引用的单元格的引用的引用 | E26: {=INDIRECT(F26&26)} -> 0 | F26: H25 | H26: 222
E27: {=INDIRECT("H"&F27)} -> 333 | F27: 27 | H27: 333
D28: TRUE 或省略，A1-样式 | E28: {=INDIRECT(F28,G28)} -> 444 | F28: H28 | G28: TRUE | H28: 444
D29: FALSE，R1C1 样式 | E29: {=INDIRECT(F29,G29)} -> 555 | F29: R29C8 | G29: FALSE | H29: 555
A31: ROW | B31: 返回引用的行号 | C31: ROW([reference]) | D31: [reference] 可选。需要得到其行号的单元格或单元格区域 | E31: 结果
E32: =ROW() -> 32
E33: =ROW(F32) -> 32
E34: {=ROW(F32:F33)} -> 32
E35: 33
E36: {=ROW(F32:G32)} -> 32
A38: ROWS | B38: 返回引用或数组的行数 | C38: ROWS(array) | D38: array 数组、数组公式或对单元格区域的引用 | E38: 结果
E39: =ROWS(F38:I39) -> 2
A41: COLUMN | B41: 参见COLUMN | E41: 结果
A42: COLUMNS | B42: 参见COLUMNS | E42: =COLUMN() -> 5
E43: =COLUMNS(F43:I43) -> 4
A45: XLOOKUP 函数是 VLOOKUP、HLOOKUP 的改进版本，建议直接使用 XLOOLUP，遇到不支持 XLOOKUP 的早期Office版本，除了使用 VLOOKUP、HLOOKUP，也可以组合使用 INDEX + MATCH 代替。 VLOOKUP、HLOOKUP 略。
A46: INDEX | B46: 数组形式：通过行号和列号索引返回元素的值（当第一个参数为数组常量时） | C46: INDEX(array, row_num, [column_num]) | D46: 略，详见帮助文档 | E46: 结果 | F46: array | I46: row_num
E47: {=INDEX(F47:H49,I47,I49)} -> 5 | F47: 1 | G47: 2 | H47: 3 | I47: 2
E48: {=INDEX(F48:H48,I49)} -> 5 | F48: 4 | G48: 5 | H48: 6 | I48: [column_num]
E49: {=INDEX(G47:G49,I47)} -> 5 | F49: 7 | G49: 8 | H49: 9 | I49: 2
...

Sheet 逻辑判断
A1: 函数 | B1: 说明摘要 | C1: 语法 | D1: 参数说明 | E1: 使用示例
A2: IF | B2: 对值和期待值进行逻辑比较 | C2: IF(logical_test, value_if_true, [value_if_false]) | D2: logical_test 必需 | E2: 结果 | F2: logical_test | G2: logical_test | H2: value_if_true | I2: value_if_false
D3: value_if_true 必需 | E3: =IF(F3<G3,H3) -> YES | F3: 1 | G3: 2 | H3: YES
D4: value_if_false 可选 | E4: =IF(F4>G4,H4,I4) -> NO | F4: 1 | G4: 2 | H4: YES | I4: NO
A6: IFS | B6: 检查是否满足一个或多个条件，且返回符合第一个 TRUE 条件的值 | C6: IFS(logical_test1, value_if_true1, [logical_test2, value_if_true2], [logical_test3, value_if_true3],…) | D6: logical_test1 必需。计算结果为 TRUE 或 FALSE 的条件 | E6: 结果 | H6: value_if_true1
E7: {=_xlfn.IFS(F7>G8,H7,F7>G10,H9,F7>G12,H11,F7<G12,H13)} -> A | F7: 120 | H7: A
D8: value_if_true1 必需 | G8: 100
D9: logical_test2…logical_test127 可选 | E9: {=_xlfn.IFS(F9>G8,H7,F9>G10,H9,F9>G12,H11,F9<G12,H13)} -> B | F9: 70 | H9: B
G10: 60
D11: value_if_true2…value_if_true127 可选 | E11: {=_xlfn.IFS(F11>G8,H7,F11>G10,H9,F11>G12,H11,F11<G12,H13)} -> C | F11: 40 | H11: C
G12: 0
E13: {=_xlfn.IFS(F13>G8,H7,F13>G10,H9,F13>G12,H11,F13<G12,H13)} -> D | F13: -15 | H13: D
A15: IFERROR | B15: 处理公式中的错误 | C15: IFERROR(value, value_if_error) | D15: value 必需。检查是否存在错误的参数 | E15: 结果 | F15: value | G15: value_if_error
E16: =F16 -> #DIV/0! | F16: =1/0 -> #DIV/0!
C17: 评估以下错误类型：#N/A、#VALUE！、#REF！、#DIV/0！、#NUM！、#NAME？或 #NULL！ | D17: value_if_error 必需。公式计算结果为错误时要返回的值 | E17: =IFERROR(F17,G17) -> 0 | F17: =1/0 -> #DIV/0! | G17: 0
E18: =F18 -> #NAME? | F18: {=5+A} -> #NAME?
E19: =IFERROR(F19,G19) -> 0 | F19: {=5+A} -> #NAME? | G19: 0
A21: AND | B21: 确定测试中的所有条件是否均为 TRUE | C21: AND(logical1, [logical2], ...) | D21: Logical1 必填 | E21: 结果 | F21: Logical1 | G21: Logical2
D22: Logical2, … 可选。最多 255 个条件 | E22: =AND(F22,G22) -> FALSE | F22: TRUE | G22: FALSE
E23: =AND(F23,G23) -> FALSE | F23: FALSE | G23: TRUE
E24: =AND(F24,G24) -> TRUE | F24: TRUE | G24: TRUE
A26: OR | B26: 确定测试中的所有条件是否均为 TRUE | C26: OR(logical1, [logical2], ...) | D26: Logical1 必填 | E26: 结果 | F26: Logical1 | G26: Logical2
D27: Logical2, … 可选。最多 255 个条件 | E27: =OR(F27,G27) -> TRUE | F27: TRUE | G27: FALSE
E28: =OR(F28,G28) -> TRUE | F28: FALSE | G28: TRUE
E29: =OR(F29,G29) -> TRUE | F29: TRUE | G29: TRUE
A31: NOT | B31: 对其参数的值进行求反 | C31: NOT(Logical) | D31: Logical 必需。计算结果为 TRUE 或 FALSE 的任何值或表达式 | E31: 结果 | F31: Logical
E32: =NOT(F32) -> FALSE | F32: TRUE
E33: =NOT(F33) -> TRUE | F33: FALSE

Sheet 日期时间
A1: 函数 | B1: 说明摘要 | C1: 语法 | D1: 参数说明 | E1: 使用示例
A2: TODAY | B2: 返回当前日期的序列号 | C2: TODAY() | D2: 没有参数 | E2: 结果
E3: =TODAY() -> 46030 | F3: Excel会将单元格格式更改为“日期”
A5: NOW | B5: 返回当前日期和时间的序列号 | C5: Now() | D5: 没有参数 | E5: 结果
E6: =NOW() -> 46030.616 | F6: Excel 会更改单元格格式
A8: DATE | B8: 返回表示特定日期的连续序列号 | C8: DATE(year,month,day) | D8: year 必需 | E8: 结果 | F8: year | G8: month | H8: day
D9: month 必需 | E9: =DATE(F9,G9,H9) -> 46022 | F9: 2025 | G9: 12 | H9: 31
D10: day 必需
A12: YEAR | B12: 返回对应于某个日期的年份 | C12: YEAR(serial_number) | D12: Serial_number 必需。要查找的年份的日期 | E12: 结果 | F12: serial_number
E13: =YEAR(F13) -> 2026 | F13: =TODAY() -> 46030
E14: =YEAR(F14)-G14 -> 44 | F14: =TODAY() -> 46030 | G14: 1982
A16: MONTH | B16: 返回日期（以序列数表示）中的月份 | C16: MONTH(serial_number) | D16: Serial_number 必需。要查找的年份的日期 | E16: 结果 | F16: serial_number
E17: =MONTH(F17) -> 1 | F17: =TODAY() -> 46030
A19: DAY | B19: 返回以序列数表示的某日期的天数 | C19: DAY(serial_number) | D19: Serial_number 必需。要查找的年份的日期 | E19: 结果 | F19: serial_number
E20: =DAY(F20) -> 8 | F20: =TODAY() -> 46030
A22: DAYS | B22: 返回两个日期之间的天数 | C22: DAYS(end_date, start_date) | D22: Start_date 和 End_date 是用于计算期间天数的起止日期 | E22: 结果 | F22: End_date | G22: Start_date
E23: =_xlfn.DAYS(F23,G23) -> 364 | F23: 46022 | G23: 45658
E24: =F23-G23 -> 364
A26: WEEKDAY | B26: 返回对应于某个日期的一周中的第几天 | C26: WEEKDAY(serial_number,[return_type]) | D26: Serial_number 必需 | E26: 结果
E27: =WEEKDAY(G27) -> 5 | F27: Serial_number | G27: =TODAY() -> 46030
E28: =WEEKDAY(G28,I28) -> 4 | F28: Serial_number | G28: =TODAY() -> 46030 | H28: Return_type | I28: 2
E29: =WEEKDAY(G29,I29) -> 3 | F29: Serial_number | G29: 46022 | H29: Return_type | I29: 2
B30: Return_type | C30: 返回的数字
B31: 1 或省略 | C31: 数字 1（星期日）到 7（星期六）。 同 Microsoft Excel 早期版本。
B32: 2 | C32: 数字 1（星期一）到 7（星期日）。
B33: 3 | C33: 数字 0（星期一）到 6（星期日）。
B34: 11 | C34: 数字 1（星期一）到 7（星期日）。
B35: 1.2 | C35: 数字 1（星期二）到数字 7（星期一）。
B36: 1.3 | C36: 数字 1（星期三）到数字 7（星期二）。
B37: 14 | C37: 数字 1（星期四）到数字 7（星期三）。
B38: 15 | C38: 数字 1（星期五）到数字 7（星期四）。
B39: 16 | C39: 数字 1（星期六）到数字 7（星期五）。
B40: 17 | C40: 数字 1（星期日）到 7（星期六）。

Sheet 数学
A1: 函数 | B1: 说明摘要 | C1: 语法 | D1: 参数说明 | E1: 使用示例
A2: ROUND | B2: 将数字四舍五入到指定的位数 | C2: ROUND(number, num_digits) | D2: number 必需。要四舍五入的数字 | E2: 结果 | F2: number | G2: num_digits
E3: =ROUND(F3,G3) -> 3.1416 | F3: 3.1415926 | G3: 4
A5: ROUNDUP | B5: 将数字进行向上舍入到指定的位数 | C5: ROUNDUP(number, num_digits) | D5: number 必需。要四舍五入的数字 | E5: =ROUNDUP(F5,G5) -> 3.1416 | F5: 3.1415926 | G5: 4
A8: ROUNDDOWN | B8: 将数字进行向下舍入到指定的位数 | C8: ROUNDDOWN(number, num_digits) | D8: number 必需。要四舍五入的数字 | E8: =ROUNDDOWN(F8,G8) -> 3.1415 | F8: 3.1415926 | G8: 4
A11: ABS | B11: 返回数字的绝对值 | C11: ABS(number) | D11: number 必需。需要计算其绝对值的实数 | E11: 结果 | F11: number
E12: =ABS(F12) -> 3.14 | F12: -3.14
E13: =ABS(F13) -> 0 | F13: 0
E14: =ABS(F14) -> 3.14 | F14: 3.14
A16: MOD | B16: 返回两数相除的余数。结果的符号与除数相同 | C16: MOD(number, divisor) | D16: number 必需。被除数 | E16: 结果 | F16: number | G16: divisor
D17: divisor 必需。除数 | E17: =MOD(F17,G17) -> 1 | F17: 3 | G17: 2
A19: RAND | B19: 返回了一个大于等于 0 且小于 1 的平均分布的随机实数 | C19: RAND() | D19: 没有参数 | E19: 结果
E20: =RAND() -> 0.50017802
A23: RANDBETWEEN | B23: 返回位于两个指定数之间的一个随机整数 | C23: RANDBETWEEN(bottom, top) | D23: bottom 必需。最小整数 | E23: 结果 | F23: bottom | G23: top
D24: top 必需。最大整数 | E24: =RANDBETWEEN(F24,G24) -> 60 | F24: 1 | G24: 100

Sheet 动态阵列
A1: 函数 | B1: 说明摘要 | C1: 语法 | D1: 参数说明 | E1: 使用示例
A2: FILTER | B2: 基于布尔值 (True/False) 数组筛选数组 | C2: FILTER(array,include,[if_empty]) | D2: array 必需。要筛选的数组或区域 | E2: include | F2: A | G2: [if_empty] | H2: 0
E3: Col A | F3: Col B | G3: Col C | H3: Col D | I3: Col E
C4: [if_empty] 可选。所含数组中的所有值都为空（筛选器不返回任何内容）时返回的值 | D4: include 必需。布尔值数组 | E4: {=_xlfn._xlws.FILTER(A115:E124,B115:B124=F2,H2)} -> Row 1 | F4: A | G4: 甲 | H4: 3 | I4: 51
E5: Row 6 | F5: A | G5: 乙 | H5: 9 | I5: 48
A7: SORT | B7: 将返回数组中排序的元素数组 | C7: SORT(array,[sort_index],[sort_order],[by_col]) | D7: [sort_index] 可选。一个数字，表示要按其排序的行或列 | E7: [sort_index] | F7: [sort_order] | G7: [by_col]
E8: 2 | F8: 1 | G8: FALSE
E9: Col A | F9: Col B | G9: Col C | H9: Col D | I9: Col E
D10: [sort_order] 可选。1 表示升序（默认值），-1 表示降序 | E10: {=_xlfn._xlws.SORT(A115:E124,E8,F8,G8)} -> Row 1 | F10: A | G10: 甲 | H10: 3 | I10: 51
E11: Row 6 | F11: A | G11: 乙 | H11: 9 | I11: 48
E12: Row 2 | F12: B | G12: 乙 | H12: 5 | I12: 67
D13: [by_col] 可选。False 表示按行排序（默认值），True 表示按列排序 | E13: Row 3 | F13: B | G13: 丙 | H13: 7 | I13: 43
E14: Row 4 | F14: C | G14: 甲 | H14: 3 | I14: 77
E15: Row 5 | F15: D | G15: 丙 | H15: 5 | I15: 43
E16: Row 10 | F16: D | G16: 丙 | H16: 6 | I16: 25
E17: Row 7 | F17: E | G17: 丙 | H17: 10 | I17: 19
E18: Row 8 | F18: F | G18: 甲 | H18: 8 | I18: 34
E19: Row 9 | F19: G | G19: 乙 | H19: 4 | I19: 55
A21: SORTBY | B21: 基于相应范围或数组中的值对范围或数组的内容进行排序 | C21: SORTBY(array, by_array1, [sort_order1], [by_array2, sort_order2],…) | D21: array 必需。要进行排序的数组或区域 | E21: [sort_order1] | F21: [sort_order2]
E22: 1 | F22: -1
D23: by_array 要对其进行排序的数组或区域 | E23: Col A | F23: Col B | G23: Col C | H23: Col D | I23: Col E
E24: {=_xlfn.SORTBY(A115:E124,B115:B124,E22,F115:F124,F22)} -> Row 6 | F24: A | G24: 乙 | H24: 9 | I24: 48
D25: [sort_order] 1 表示升序，-1 表示降序。 默认为升序 | E25: Row 1 | F25: A | G25: 甲 | H25: 3 | I25: 51
E26: Row 3 | F26: B | G26: 丙 | H26: 7 | I26: 43
E27: Row 2 | F27: B | G27: 乙 | H27: 5 | I27: 67
E28: Row 4 | F28: C | G28: 甲 | H28: 3 | I28: 77
E29: Row 10 | F29: D | G29: 丙 | H29: 6 | I29: 25
E30: Row 5 | F30: D | G30: 丙 | H30: 5 | I30: 43
E31: Row 7 | F31: E | G31: 丙 | H31: 10 | I31: 19
E32: Row 8 | F32: F | G32: 甲 | H32: 8 | I32: 34
E33: Row 9 | F33: G | G33: 乙 | H33: 4 | I33: 55
A35: UNIQUE | B35: 函数返回列表或范围中的一系列唯一值 | C35: UNIQUE (array，[by_col]，[exactly_once]) | D35: [by_col] 可选。TRUE 将相互比较列并返回唯一列。FALSE (或省略) 将相互比较行并返回唯一行 | E35: [by_col] | F35: FALSE | G35: [exactly_once] | H35: FALSE
E36: Col B | G36: Col B | H36: Col C
E37: {=_xlfn.UNIQUE(B115:B124,F35,H35)} -> A | G37: {=_xlfn.UNIQUE(B115:C124,F35,H35)} -> A | H37: 甲
E38: B | G38: B | H38: 乙
E39: C | G39: B | H39: 丙
D40: [exactly_once] 可选。TRUE 将返回区域或数组中发生一次的所有非重复行或列。FALSE (或省略) 将返回区域或数组中的所有不同行或列 | E40: D | G40: C | H40: 甲
E41: E | G41: D | H41: 丙
E42: F | G42: A | H42: 乙
E43: G | G43: E | H43: 丙
...
